<?xml version="1.0" encoding="utf-8"?>
<!-- This URDF was automatically created by SolidWorks to URDF Exporter! Originally created by Stephen Brawner (brawner@gmail.com) 
     Commit Version: 1.6.0-4-g7f85cfe  Build Version: 1.6.7995.38578
     For more information, please see http://wiki.ros.org/sw_urdf_exporter -->
<robot
  name="00-SCARA">
  <link
    name="BASE">
    <inertial>
      <origin
        xyz="7.16421917942135E-05 1.3542109605614E-05 0.18099571236549"
        rpy="0 0 0" />
      <mass
        value="1.46804980186314" />
      <inertia
        ixx="0.00842920035948805"
        ixy="3.50262874031246E-07"
        ixz="-6.38631458412278E-07"
        iyy="0.0084253370773801"
        iyz="2.17446352849247E-07"
        izz="0.00253728833651902" />
    </inertial>
    <visual>
      <origin
        xyz="0 0 0"
        rpy="0 0 0" />
      <geometry>
        <mesh
          filename="package://00-SCARA/meshes/BASE.STL" />
      </geometry>
      <material
        name="">
        <color
          rgba="0.752941176470588 0.752941176470588 0.752941176470588 1" />
      </material>
    </visual>
    <collision>
      <origin
        xyz="0 0 0"
        rpy="0 0 0" />
      <geometry>
        <mesh
          filename="package://00-SCARA/meshes/BASE.STL" />
      </geometry>
    </collision>
  </link>
  <link
    name="LINK1">
    <inertial>
      <origin
        xyz="0.0484139248726095 2.20590711719829E-05 0.346949698783894"
        rpy="0 0 0" />
      <mass
        value="0.668715038402639" />
      <inertia
        ixx="0.000501755011560242"
        ixy="8.38768282365564E-08"
        ixz="-6.84412359363594E-05"
        iyy="0.00248735615221583"
        iyz="-1.16431826234763E-07"
        izz="0.00287940086983324" />
    </inertial>
    <visual>
      <origin
        xyz="0 0 0"
        rpy="0 0 0" />
      <geometry>
        <mesh
          filename="package://00-SCARA/meshes/LINK1.STL" />
      </geometry>
      <material
        name="">
        <color
          rgba="0.752941176470588 0.752941176470588 0.752941176470588 1" />
      </material>
    </visual>
    <collision>
      <origin
        xyz="0 0 0"
        rpy="0 0 0" />
      <geometry>
        <mesh
          filename="package://00-SCARA/meshes/LINK1.STL" />
      </geometry>
    </collision>
  </link>
  <joint
    name="LINK1"
    type="revolute">
    <origin
      xyz="0 0 0"
      rpy="1.5708 -0.04709 0" />
    <parent
      link="BASE" />
    <child
      link="LINK1" />
    <axis
      xyz="0 0 0" />
    <limit
      lower="0"
      upper="0"
      effort="0"
      velocity="0" />
  </joint>
  <link
    name="LINK2">
    <inertial>
      <origin
        xyz="0.26069645933821 -0.00262206848028845 0.400468073597669"
        rpy="0 0 0" />
      <mass
        value="1.1127699658662" />
      <inertia
        ixx="0.00117171893333024"
        ixy="-3.93427635773306E-05"
        ixz="-4.12603973995657E-05"
        iyy="0.00276702775036591"
        iyz="-3.9153357792706E-05"
        izz="0.00227111088419481" />
    </inertial>
    <visual>
      <origin
        xyz="0 0 0"
        rpy="0 0 0" />
      <geometry>
        <mesh
          filename="package://00-SCARA/meshes/LINK2.STL" />
      </geometry>
      <material
        name="">
        <color
          rgba="0.752941176470588 0.752941176470588 0.752941176470588 1" />
      </material>
    </visual>
    <collision>
      <origin
        xyz="0 0 0"
        rpy="0 0 0" />
      <geometry>
        <mesh
          filename="package://00-SCARA/meshes/LINK2.STL" />
      </geometry>
    </collision>
  </link>
  <joint
    name="LINK2"
    type="revolute">
    <origin
      xyz="0.096154 -0.18006 -0.010468"
      rpy="0 0 1.0603" />
    <parent
      link="LINK1" />
    <child
      link="LINK2" />
    <axis
      xyz="0 0 0" />
    <limit
      lower="0"
      upper="0"
      effort="0"
      velocity="0" />
  </joint>
  <link
    name="LINK3">
    <inertial>
      <origin
        xyz="0.286364755860275 0.137620160192424 0.0119164688096812"
        rpy="0 0 0" />
      <mass
        value="0.0166188372093739" />
      <inertia
        ixx="2.75996511157422E-06"
        ixy="-1.98901191773345E-06"
        ixz="9.85700114150892E-08"
        iyy="3.20803397608032E-06"
        iyz="8.80907775098542E-08"
        izz="5.20478749973822E-06" />
    </inertial>
    <visual>
      <origin
        xyz="0 0 0"
        rpy="0 0 0" />
      <geometry>
        <mesh
          filename="package://00-SCARA/meshes/LINK3.STL" />
      </geometry>
      <material
        name="">
        <color
          rgba="0.752941176470588 0.752941176470588 0.752941176470588 1" />
      </material>
    </visual>
    <collision>
      <origin
        xyz="0 0 0"
        rpy="0 0 0" />
      <geometry>
        <mesh
          filename="package://00-SCARA/meshes/LINK3.STL" />
      </geometry>
    </collision>
  </link>
  <joint
    name="LINK3"
    type="prismatic">
    <origin
      xyz="0.028418 0.085576 0.58862"
      rpy="0 0 -0.72932" />
    <parent
      link="LINK2" />
    <child
      link="LINK3" />
    <axis
      xyz="0 0 1" />
    <limit
      lower="0"
      upper="0"
      effort="0"
      velocity="0" />
  </joint>
  <link
    name="LINK4">
    <inertial>
      <origin
        xyz="-0.000960020981620902 -0.000859185726028208 -0.0344702469292239"
        rpy="0 0 0" />
      <mass
        value="0.0164150189496518" />
      <inertia
        ixx="8.38365885393722E-06"
        ixy="-9.13058924333034E-08"
        ixz="2.90788083077103E-08"
        iyy="8.40396490526716E-06"
        iyz="2.60245322806172E-08"
        izz="3.12987842968931E-06" />
    </inertial>
    <visual>
      <origin
        xyz="0 0 0"
        rpy="0 0 0" />
      <geometry>
        <mesh
          filename="package://00-SCARA/meshes/LINK4.STL" />
      </geometry>
      <material
        name="">
        <color
          rgba="0.752941176470588 0.752941176470588 0.752941176470588 1" />
      </material>
    </visual>
    <collision>
      <origin
        xyz="0 0 0"
        rpy="0 0 0" />
      <geometry>
        <mesh
          filename="package://00-SCARA/meshes/LINK4.STL" />
      </geometry>
    </collision>
  </link>
  <joint
    name="LINK4"
    type="revolute">
    <origin
      xyz="0.30441 0.15374 -0.1284"
      rpy="0 0 0.075584" />
    <parent
      link="LINK3" />
    <child
      link="LINK4" />
    <axis
      xyz="0 0 1" />
    <limit
      lower="0"
      upper="0"
      effort="0"
      velocity="0" />
  </joint>
  <link
    name="GRIPPER">
    <inertial>
      <origin
        xyz="-0.000447070545206485 0.0039430481967168 -0.127670775825744"
        rpy="0 0 0" />
      <mass
        value="0.135596532339296" />
      <inertia
        ixx="0.000715616364121439"
        ixy="-2.00799723245443E-06"
        ixz="1.95608237868685E-06"
        iyy="0.000722668105282603"
        iyz="1.43527550448802E-06"
        izz="2.42028221106115E-05" />
    </inertial>
    <visual>
      <origin
        xyz="0 0 0"
        rpy="0 0 0" />
      <geometry>
        <mesh
          filename="package://00-SCARA/meshes/GRIPPER.STL" />
      </geometry>
      <material
        name="">
        <color
          rgba="0.752941176470588 0.752941176470588 0.752941176470588 1" />
      </material>
    </visual>
    <collision>
      <origin
        xyz="0 0 0"
        rpy="0 0 0" />
      <geometry>
        <mesh
          filename="package://00-SCARA/meshes/GRIPPER.STL" />
      </geometry>
    </collision>
  </link>
  <joint
    name="GRIPPER"
    type="continuous">
    <origin
      xyz="0 0 0"
      rpy="0 0 0.42243" />
    <parent
      link="LINK4" />
    <child
      link="GRIPPER" />
    <axis
      xyz="0 0 1" />
  </joint>
</robot>